{"uuid": "4ce7e1fc-1208-494a-9131-63578d439d22", "children": ["a3043a36-86cb-491b-8b17-be8b618b7f24", "1ceb689e-c286-4c6c-9de6-c440aa5d0d28", "ed661b7d-4a0a-4438-a3f0-f31e6cb8419e", "1ce6a8b5-2b5c-45b6-81cb-53b4a948a151"], "befores": [{"name": "_xunit_setup_class_fixture_TestCase", "status": "failed", "statusDetails": {"message": "Failed: setup_class: 未获取到 token\n", "trace": "  File \"D:\\my_venv\\myenv\\Lib\\site-packages\\pluggy\\_callers.py\", line 38, in run_old_style_hookwrapper\n    res = yield\n          ^^^^^\n  File \"D:\\my_venv\\myenv\\Lib\\site-packages\\pluggy\\_callers.py\", line 139, in _multicall\n    teardown.throw(exception)\n  File \"D:\\my_venv\\myenv\\Lib\\site-packages\\pluggy\\_callers.py\", line 53, in run_old_style_hookwrapper\n    return result.get_result()\n           ^^^^^^^^^^^^^^^^^^^\n  File \"D:\\my_venv\\myenv\\Lib\\site-packages\\pluggy\\_result.py\", line 103, in get_result\n    raise exc.with_traceback(tb)\n  File \"D:\\my_venv\\myenv\\Lib\\site-packages\\pluggy\\_callers.py\", line 38, in run_old_style_hookwrapper\n    res = yield\n          ^^^^^\n  File \"D:\\my_venv\\myenv\\Lib\\site-packages\\pluggy\\_callers.py\", line 139, in _multicall\n    teardown.throw(exception)\n  File \"D:\\my_venv\\myenv\\Lib\\site-packages\\_pytest\\setuponly.py\", line 36, in pytest_fixture_setup\n    return (yield)\n            ^^^^^\n  File \"D:\\my_venv\\myenv\\Lib\\site-packages\\pluggy\\_callers.py\", line 121, in _multicall\n    res = hook_impl.function(*args)\n          ^^^^^^^^^^^^^^^^^^^^^^^^^\n  File \"D:\\my_venv\\myenv\\Lib\\site-packages\\_pytest\\fixtures.py\", line 1195, in pytest_fixture_setup\n    result = call_fixture_func(fixturefunc, request, kwargs)\n             ^^^^^^^^^^^^^^^^^^^^^^^^^^^^^^^^^^^^^^^^^^^^^^^\n  File \"D:\\my_venv\\myenv\\Lib\\site-packages\\_pytest\\fixtures.py\", line 922, in call_fixture_func\n    fixture_result = next(generator)\n                     ^^^^^^^^^^^^^^^\n  File \"D:\\my_venv\\myenv\\Lib\\site-packages\\_pytest\\python.py\", line 792, in xunit_setup_class_fixture\n    _call_with_optional_argument(func, cls)\n  File \"D:\\my_venv\\myenv\\Lib\\site-packages\\_pytest\\python.py\", line 720, in _call_with_optional_argument\n    func(arg)\n  File \"D:\\pythonProject3\\autotest_api\\test_case\\test_pending_risk_event\\test_risk_high.py\", line 30, in setup_class\n    pytest.fail(\"setup_class: 未获取到 token\")\n  File \"D:\\my_venv\\myenv\\Lib\\site-packages\\_pytest\\outcomes.py\", line 177, in fail\n    raise Failed(msg=reason, pytrace=pytrace)\n"}, "steps": [{"name": "【风险】-【风险事件列表】接口", "status": "failed", "statusDetails": {"message": "Failed: setup_class: 未获取到 token\n", "trace": "  File \"D:\\pythonProject3\\autotest_api\\test_case\\test_pending_risk_event\\test_risk_high.py\", line 30, in setup_class\n    pytest.fail(\"setup_class: 未获取到 token\")\n  File \"D:\\my_venv\\myenv\\Lib\\site-packages\\_pytest\\outcomes.py\", line 177, in fail\n    raise Failed(msg=reason, pytrace=pytrace)\n"}, "start": 1754031297964, "stop": 1754031297965}], "start": 1754031297964, "stop": 1754031297975}, {"name": "_xunit_setup_class_fixture_TestCase", "status": "failed", "statusDetails": {"message": "Failed: setup_class: 未获取到 token\n", "trace": "  File \"D:\\my_venv\\myenv\\Lib\\site-packages\\pluggy\\_callers.py\", line 38, in run_old_style_hookwrapper\n    res = yield\n          ^^^^^\n  File \"D:\\my_venv\\myenv\\Lib\\site-packages\\pluggy\\_callers.py\", line 139, in _multicall\n    teardown.throw(exception)\n  File \"D:\\my_venv\\myenv\\Lib\\site-packages\\pluggy\\_callers.py\", line 53, in run_old_style_hookwrapper\n    return result.get_result()\n           ^^^^^^^^^^^^^^^^^^^\n  File \"D:\\my_venv\\myenv\\Lib\\site-packages\\pluggy\\_result.py\", line 103, in get_result\n    raise exc.with_traceback(tb)\n  File \"D:\\my_venv\\myenv\\Lib\\site-packages\\pluggy\\_callers.py\", line 38, in run_old_style_hookwrapper\n    res = yield\n          ^^^^^\n  File \"D:\\my_venv\\myenv\\Lib\\site-packages\\pluggy\\_callers.py\", line 139, in _multicall\n    teardown.throw(exception)\n  File \"D:\\my_venv\\myenv\\Lib\\site-packages\\_pytest\\setuponly.py\", line 36, in pytest_fixture_setup\n    return (yield)\n            ^^^^^\n  File \"D:\\my_venv\\myenv\\Lib\\site-packages\\pluggy\\_callers.py\", line 121, in _multicall\n    res = hook_impl.function(*args)\n          ^^^^^^^^^^^^^^^^^^^^^^^^^\n  File \"D:\\my_venv\\myenv\\Lib\\site-packages\\_pytest\\fixtures.py\", line 1195, in pytest_fixture_setup\n    result = call_fixture_func(fixturefunc, request, kwargs)\n             ^^^^^^^^^^^^^^^^^^^^^^^^^^^^^^^^^^^^^^^^^^^^^^^\n  File \"D:\\my_venv\\myenv\\Lib\\site-packages\\_pytest\\fixtures.py\", line 922, in call_fixture_func\n    fixture_result = next(generator)\n                     ^^^^^^^^^^^^^^^\n  File \"D:\\my_venv\\myenv\\Lib\\site-packages\\_pytest\\python.py\", line 792, in xunit_setup_class_fixture\n    _call_with_optional_argument(func, cls)\n  File \"D:\\my_venv\\myenv\\Lib\\site-packages\\_pytest\\python.py\", line 720, in _call_with_optional_argument\n    func(arg)\n  File \"D:\\pythonProject3\\autotest_api\\test_case\\test_pending_risk_event\\test_risk_high.py\", line 30, in setup_class\n    pytest.fail(\"setup_class: 未获取到 token\")\n  File \"D:\\my_venv\\myenv\\Lib\\site-packages\\_pytest\\outcomes.py\", line 177, in fail\n    raise Failed(msg=reason, pytrace=pytrace)\n"}, "steps": [{"name": "【风险】-【风险事件列表】接口", "status": "failed", "statusDetails": {"message": "Failed: setup_class: 未获取到 token\n", "trace": "  File \"D:\\pythonProject3\\autotest_api\\test_case\\test_pending_risk_event\\test_risk_high.py\", line 30, in setup_class\n    pytest.fail(\"setup_class: 未获取到 token\")\n  File \"D:\\my_venv\\myenv\\Lib\\site-packages\\_pytest\\outcomes.py\", line 177, in fail\n    raise Failed(msg=reason, pytrace=pytrace)\n"}, "start": 1754031298993, "stop": 1754031298993}], "start": 1754031298993, "stop": 1754031298994}, {"name": "_xunit_setup_class_fixture_TestCase", "status": "failed", "statusDetails": {"message": "Failed: setup_class: 未获取到 token\n", "trace": "  File \"D:\\my_venv\\myenv\\Lib\\site-packages\\pluggy\\_callers.py\", line 38, in run_old_style_hookwrapper\n    res = yield\n          ^^^^^\n  File \"D:\\my_venv\\myenv\\Lib\\site-packages\\pluggy\\_callers.py\", line 139, in _multicall\n    teardown.throw(exception)\n  File \"D:\\my_venv\\myenv\\Lib\\site-packages\\pluggy\\_callers.py\", line 53, in run_old_style_hookwrapper\n    return result.get_result()\n           ^^^^^^^^^^^^^^^^^^^\n  File \"D:\\my_venv\\myenv\\Lib\\site-packages\\pluggy\\_result.py\", line 103, in get_result\n    raise exc.with_traceback(tb)\n  File \"D:\\my_venv\\myenv\\Lib\\site-packages\\pluggy\\_callers.py\", line 38, in run_old_style_hookwrapper\n    res = yield\n          ^^^^^\n  File \"D:\\my_venv\\myenv\\Lib\\site-packages\\pluggy\\_callers.py\", line 139, in _multicall\n    teardown.throw(exception)\n  File \"D:\\my_venv\\myenv\\Lib\\site-packages\\_pytest\\setuponly.py\", line 36, in pytest_fixture_setup\n    return (yield)\n            ^^^^^\n  File \"D:\\my_venv\\myenv\\Lib\\site-packages\\pluggy\\_callers.py\", line 121, in _multicall\n    res = hook_impl.function(*args)\n          ^^^^^^^^^^^^^^^^^^^^^^^^^\n  File \"D:\\my_venv\\myenv\\Lib\\site-packages\\_pytest\\fixtures.py\", line 1195, in pytest_fixture_setup\n    result = call_fixture_func(fixturefunc, request, kwargs)\n             ^^^^^^^^^^^^^^^^^^^^^^^^^^^^^^^^^^^^^^^^^^^^^^^\n  File \"D:\\my_venv\\myenv\\Lib\\site-packages\\_pytest\\fixtures.py\", line 922, in call_fixture_func\n    fixture_result = next(generator)\n                     ^^^^^^^^^^^^^^^\n  File \"D:\\my_venv\\myenv\\Lib\\site-packages\\_pytest\\python.py\", line 792, in xunit_setup_class_fixture\n    _call_with_optional_argument(func, cls)\n  File \"D:\\my_venv\\myenv\\Lib\\site-packages\\_pytest\\python.py\", line 720, in _call_with_optional_argument\n    func(arg)\n  File \"D:\\pythonProject3\\autotest_api\\test_case\\test_pending_risk_event\\test_risk_high.py\", line 30, in setup_class\n    pytest.fail(\"setup_class: 未获取到 token\")\n  File \"D:\\my_venv\\myenv\\Lib\\site-packages\\_pytest\\outcomes.py\", line 177, in fail\n    raise Failed(msg=reason, pytrace=pytrace)\n"}, "steps": [{"name": "【风险】-【风险事件列表】接口", "status": "failed", "statusDetails": {"message": "Failed: setup_class: 未获取到 token\n", "trace": "  File \"D:\\pythonProject3\\autotest_api\\test_case\\test_pending_risk_event\\test_risk_high.py\", line 30, in setup_class\n    pytest.fail(\"setup_class: 未获取到 token\")\n  File \"D:\\my_venv\\myenv\\Lib\\site-packages\\_pytest\\outcomes.py\", line 177, in fail\n    raise Failed(msg=reason, pytrace=pytrace)\n"}, "start": 1754031300014, "stop": 1754031300014}], "start": 1754031300013, "stop": 1754031300014}, {"name": "_xunit_setup_class_fixture_TestCase", "status": "failed", "statusDetails": {"message": "Failed: setup_class: 未获取到 token\n", "trace": "  File \"D:\\my_venv\\myenv\\Lib\\site-packages\\pluggy\\_callers.py\", line 38, in run_old_style_hookwrapper\n    res = yield\n          ^^^^^\n  File \"D:\\my_venv\\myenv\\Lib\\site-packages\\pluggy\\_callers.py\", line 139, in _multicall\n    teardown.throw(exception)\n  File \"D:\\my_venv\\myenv\\Lib\\site-packages\\pluggy\\_callers.py\", line 53, in run_old_style_hookwrapper\n    return result.get_result()\n           ^^^^^^^^^^^^^^^^^^^\n  File \"D:\\my_venv\\myenv\\Lib\\site-packages\\pluggy\\_result.py\", line 103, in get_result\n    raise exc.with_traceback(tb)\n  File \"D:\\my_venv\\myenv\\Lib\\site-packages\\pluggy\\_callers.py\", line 38, in run_old_style_hookwrapper\n    res = yield\n          ^^^^^\n  File \"D:\\my_venv\\myenv\\Lib\\site-packages\\pluggy\\_callers.py\", line 139, in _multicall\n    teardown.throw(exception)\n  File \"D:\\my_venv\\myenv\\Lib\\site-packages\\_pytest\\setuponly.py\", line 36, in pytest_fixture_setup\n    return (yield)\n            ^^^^^\n  File \"D:\\my_venv\\myenv\\Lib\\site-packages\\pluggy\\_callers.py\", line 121, in _multicall\n    res = hook_impl.function(*args)\n          ^^^^^^^^^^^^^^^^^^^^^^^^^\n  File \"D:\\my_venv\\myenv\\Lib\\site-packages\\_pytest\\fixtures.py\", line 1195, in pytest_fixture_setup\n    result = call_fixture_func(fixturefunc, request, kwargs)\n             ^^^^^^^^^^^^^^^^^^^^^^^^^^^^^^^^^^^^^^^^^^^^^^^\n  File \"D:\\my_venv\\myenv\\Lib\\site-packages\\_pytest\\fixtures.py\", line 922, in call_fixture_func\n    fixture_result = next(generator)\n                     ^^^^^^^^^^^^^^^\n  File \"D:\\my_venv\\myenv\\Lib\\site-packages\\_pytest\\python.py\", line 792, in xunit_setup_class_fixture\n    _call_with_optional_argument(func, cls)\n  File \"D:\\my_venv\\myenv\\Lib\\site-packages\\_pytest\\python.py\", line 720, in _call_with_optional_argument\n    func(arg)\n  File \"D:\\pythonProject3\\autotest_api\\test_case\\test_pending_risk_event\\test_risk_high.py\", line 30, in setup_class\n    pytest.fail(\"setup_class: 未获取到 token\")\n  File \"D:\\my_venv\\myenv\\Lib\\site-packages\\_pytest\\outcomes.py\", line 177, in fail\n    raise Failed(msg=reason, pytrace=pytrace)\n"}, "steps": [{"name": "【风险】-【风险事件列表】接口", "status": "failed", "statusDetails": {"message": "Failed: setup_class: 未获取到 token\n", "trace": "  File \"D:\\pythonProject3\\autotest_api\\test_case\\test_pending_risk_event\\test_risk_high.py\", line 30, in setup_class\n    pytest.fail(\"setup_class: 未获取到 token\")\n  File \"D:\\my_venv\\myenv\\Lib\\site-packages\\_pytest\\outcomes.py\", line 177, in fail\n    raise Failed(msg=reason, pytrace=pytrace)\n"}, "start": 1754031301035, "stop": 1754031301035}], "start": 1754031301034, "stop": 1754031301036}], "start": 1754031301034, "stop": 1754031301047}