{"uuid": "b65ca96d-4676-4920-932e-7a8eff4d6d40", "children": ["bc4fe411-9fc2-44a1-b45a-7fc4e19ab404", "84dc8fea-10bc-4988-aca6-1b3898dbf19d", "1ed97990-f55d-406b-9401-0209abd18c1d", "067fdce9-b5c1-4ee1-9403-5d7ab7c3ba72"], "befores": [{"name": "_xunit_setup_class_fixture_TestCase", "status": "failed", "statusDetails": {"message": "Failed: setup_class: 未获取到 token\n", "trace": "  File \"D:\\my_venv\\myenv\\Lib\\site-packages\\pluggy\\_callers.py\", line 38, in run_old_style_hookwrapper\n    res = yield\n          ^^^^^\n  File \"D:\\my_venv\\myenv\\Lib\\site-packages\\pluggy\\_callers.py\", line 139, in _multicall\n    teardown.throw(exception)\n  File \"D:\\my_venv\\myenv\\Lib\\site-packages\\pluggy\\_callers.py\", line 53, in run_old_style_hookwrapper\n    return result.get_result()\n           ^^^^^^^^^^^^^^^^^^^\n  File \"D:\\my_venv\\myenv\\Lib\\site-packages\\pluggy\\_result.py\", line 103, in get_result\n    raise exc.with_traceback(tb)\n  File \"D:\\my_venv\\myenv\\Lib\\site-packages\\pluggy\\_callers.py\", line 38, in run_old_style_hookwrapper\n    res = yield\n          ^^^^^\n  File \"D:\\my_venv\\myenv\\Lib\\site-packages\\pluggy\\_callers.py\", line 139, in _multicall\n    teardown.throw(exception)\n  File \"D:\\my_venv\\myenv\\Lib\\site-packages\\_pytest\\setuponly.py\", line 36, in pytest_fixture_setup\n    return (yield)\n            ^^^^^\n  File \"D:\\my_venv\\myenv\\Lib\\site-packages\\pluggy\\_callers.py\", line 121, in _multicall\n    res = hook_impl.function(*args)\n          ^^^^^^^^^^^^^^^^^^^^^^^^^\n  File \"D:\\my_venv\\myenv\\Lib\\site-packages\\_pytest\\fixtures.py\", line 1195, in pytest_fixture_setup\n    result = call_fixture_func(fixturefunc, request, kwargs)\n             ^^^^^^^^^^^^^^^^^^^^^^^^^^^^^^^^^^^^^^^^^^^^^^^\n  File \"D:\\my_venv\\myenv\\Lib\\site-packages\\_pytest\\fixtures.py\", line 922, in call_fixture_func\n    fixture_result = next(generator)\n                     ^^^^^^^^^^^^^^^\n  File \"D:\\my_venv\\myenv\\Lib\\site-packages\\_pytest\\python.py\", line 792, in xunit_setup_class_fixture\n    _call_with_optional_argument(func, cls)\n  File \"D:\\my_venv\\myenv\\Lib\\site-packages\\_pytest\\python.py\", line 720, in _call_with_optional_argument\n    func(arg)\n  File \"D:\\pythonProject3\\autotest_api\\test_case\\test_pending_risk_event\\test_risk_mid.py\", line 28, in setup_class\n    pytest.fail(\"setup_class: 未获取到 token\")\n  File \"D:\\my_venv\\myenv\\Lib\\site-packages\\_pytest\\outcomes.py\", line 177, in fail\n    raise Failed(msg=reason, pytrace=pytrace)\n"}, "steps": [{"name": "【风险】-【风险事件列表】接口", "status": "failed", "statusDetails": {"message": "Failed: setup_class: 未获取到 token\n", "trace": "  File \"D:\\pythonProject3\\autotest_api\\test_case\\test_pending_risk_event\\test_risk_mid.py\", line 28, in setup_class\n    pytest.fail(\"setup_class: 未获取到 token\")\n  File \"D:\\my_venv\\myenv\\Lib\\site-packages\\_pytest\\outcomes.py\", line 177, in fail\n    raise Failed(msg=reason, pytrace=pytrace)\n"}, "start": 1754031297966, "stop": 1754031297966}], "start": 1754031297966, "stop": 1754031297975}, {"name": "_xunit_setup_class_fixture_TestCase", "status": "failed", "statusDetails": {"message": "Failed: setup_class: 未获取到 token\n", "trace": "  File \"D:\\my_venv\\myenv\\Lib\\site-packages\\pluggy\\_callers.py\", line 38, in run_old_style_hookwrapper\n    res = yield\n          ^^^^^\n  File \"D:\\my_venv\\myenv\\Lib\\site-packages\\pluggy\\_callers.py\", line 139, in _multicall\n    teardown.throw(exception)\n  File \"D:\\my_venv\\myenv\\Lib\\site-packages\\pluggy\\_callers.py\", line 53, in run_old_style_hookwrapper\n    return result.get_result()\n           ^^^^^^^^^^^^^^^^^^^\n  File \"D:\\my_venv\\myenv\\Lib\\site-packages\\pluggy\\_result.py\", line 103, in get_result\n    raise exc.with_traceback(tb)\n  File \"D:\\my_venv\\myenv\\Lib\\site-packages\\pluggy\\_callers.py\", line 38, in run_old_style_hookwrapper\n    res = yield\n          ^^^^^\n  File \"D:\\my_venv\\myenv\\Lib\\site-packages\\pluggy\\_callers.py\", line 139, in _multicall\n    teardown.throw(exception)\n  File \"D:\\my_venv\\myenv\\Lib\\site-packages\\_pytest\\setuponly.py\", line 36, in pytest_fixture_setup\n    return (yield)\n            ^^^^^\n  File \"D:\\my_venv\\myenv\\Lib\\site-packages\\pluggy\\_callers.py\", line 121, in _multicall\n    res = hook_impl.function(*args)\n          ^^^^^^^^^^^^^^^^^^^^^^^^^\n  File \"D:\\my_venv\\myenv\\Lib\\site-packages\\_pytest\\fixtures.py\", line 1195, in pytest_fixture_setup\n    result = call_fixture_func(fixturefunc, request, kwargs)\n             ^^^^^^^^^^^^^^^^^^^^^^^^^^^^^^^^^^^^^^^^^^^^^^^\n  File \"D:\\my_venv\\myenv\\Lib\\site-packages\\_pytest\\fixtures.py\", line 922, in call_fixture_func\n    fixture_result = next(generator)\n                     ^^^^^^^^^^^^^^^\n  File \"D:\\my_venv\\myenv\\Lib\\site-packages\\_pytest\\python.py\", line 792, in xunit_setup_class_fixture\n    _call_with_optional_argument(func, cls)\n  File \"D:\\my_venv\\myenv\\Lib\\site-packages\\_pytest\\python.py\", line 720, in _call_with_optional_argument\n    func(arg)\n  File \"D:\\pythonProject3\\autotest_api\\test_case\\test_pending_risk_event\\test_risk_mid.py\", line 28, in setup_class\n    pytest.fail(\"setup_class: 未获取到 token\")\n  File \"D:\\my_venv\\myenv\\Lib\\site-packages\\_pytest\\outcomes.py\", line 177, in fail\n    raise Failed(msg=reason, pytrace=pytrace)\n"}, "steps": [{"name": "【风险】-【风险事件列表】接口", "status": "failed", "statusDetails": {"message": "Failed: setup_class: 未获取到 token\n", "trace": "  File \"D:\\pythonProject3\\autotest_api\\test_case\\test_pending_risk_event\\test_risk_mid.py\", line 28, in setup_class\n    pytest.fail(\"setup_class: 未获取到 token\")\n  File \"D:\\my_venv\\myenv\\Lib\\site-packages\\_pytest\\outcomes.py\", line 177, in fail\n    raise Failed(msg=reason, pytrace=pytrace)\n"}, "start": 1754031298992, "stop": 1754031298993}], "start": 1754031298992, "stop": 1754031298993}, {"name": "_xunit_setup_class_fixture_TestCase", "status": "failed", "statusDetails": {"message": "Failed: setup_class: 未获取到 token\n", "trace": "  File \"D:\\my_venv\\myenv\\Lib\\site-packages\\pluggy\\_callers.py\", line 38, in run_old_style_hookwrapper\n    res = yield\n          ^^^^^\n  File \"D:\\my_venv\\myenv\\Lib\\site-packages\\pluggy\\_callers.py\", line 139, in _multicall\n    teardown.throw(exception)\n  File \"D:\\my_venv\\myenv\\Lib\\site-packages\\pluggy\\_callers.py\", line 53, in run_old_style_hookwrapper\n    return result.get_result()\n           ^^^^^^^^^^^^^^^^^^^\n  File \"D:\\my_venv\\myenv\\Lib\\site-packages\\pluggy\\_result.py\", line 103, in get_result\n    raise exc.with_traceback(tb)\n  File \"D:\\my_venv\\myenv\\Lib\\site-packages\\pluggy\\_callers.py\", line 38, in run_old_style_hookwrapper\n    res = yield\n          ^^^^^\n  File \"D:\\my_venv\\myenv\\Lib\\site-packages\\pluggy\\_callers.py\", line 139, in _multicall\n    teardown.throw(exception)\n  File \"D:\\my_venv\\myenv\\Lib\\site-packages\\_pytest\\setuponly.py\", line 36, in pytest_fixture_setup\n    return (yield)\n            ^^^^^\n  File \"D:\\my_venv\\myenv\\Lib\\site-packages\\pluggy\\_callers.py\", line 121, in _multicall\n    res = hook_impl.function(*args)\n          ^^^^^^^^^^^^^^^^^^^^^^^^^\n  File \"D:\\my_venv\\myenv\\Lib\\site-packages\\_pytest\\fixtures.py\", line 1195, in pytest_fixture_setup\n    result = call_fixture_func(fixturefunc, request, kwargs)\n             ^^^^^^^^^^^^^^^^^^^^^^^^^^^^^^^^^^^^^^^^^^^^^^^\n  File \"D:\\my_venv\\myenv\\Lib\\site-packages\\_pytest\\fixtures.py\", line 922, in call_fixture_func\n    fixture_result = next(generator)\n                     ^^^^^^^^^^^^^^^\n  File \"D:\\my_venv\\myenv\\Lib\\site-packages\\_pytest\\python.py\", line 792, in xunit_setup_class_fixture\n    _call_with_optional_argument(func, cls)\n  File \"D:\\my_venv\\myenv\\Lib\\site-packages\\_pytest\\python.py\", line 720, in _call_with_optional_argument\n    func(arg)\n  File \"D:\\pythonProject3\\autotest_api\\test_case\\test_pending_risk_event\\test_risk_mid.py\", line 28, in setup_class\n    pytest.fail(\"setup_class: 未获取到 token\")\n  File \"D:\\my_venv\\myenv\\Lib\\site-packages\\_pytest\\outcomes.py\", line 177, in fail\n    raise Failed(msg=reason, pytrace=pytrace)\n"}, "steps": [{"name": "【风险】-【风险事件列表】接口", "status": "failed", "statusDetails": {"message": "Failed: setup_class: 未获取到 token\n", "trace": "  File \"D:\\pythonProject3\\autotest_api\\test_case\\test_pending_risk_event\\test_risk_mid.py\", line 28, in setup_class\n    pytest.fail(\"setup_class: 未获取到 token\")\n  File \"D:\\my_venv\\myenv\\Lib\\site-packages\\_pytest\\outcomes.py\", line 177, in fail\n    raise Failed(msg=reason, pytrace=pytrace)\n"}, "start": 1754031300014, "stop": 1754031300014}], "start": 1754031300014, "stop": 1754031300014}, {"name": "_xunit_setup_class_fixture_TestCase", "status": "failed", "statusDetails": {"message": "Failed: setup_class: 未获取到 token\n", "trace": "  File \"D:\\my_venv\\myenv\\Lib\\site-packages\\pluggy\\_callers.py\", line 38, in run_old_style_hookwrapper\n    res = yield\n          ^^^^^\n  File \"D:\\my_venv\\myenv\\Lib\\site-packages\\pluggy\\_callers.py\", line 139, in _multicall\n    teardown.throw(exception)\n  File \"D:\\my_venv\\myenv\\Lib\\site-packages\\pluggy\\_callers.py\", line 53, in run_old_style_hookwrapper\n    return result.get_result()\n           ^^^^^^^^^^^^^^^^^^^\n  File \"D:\\my_venv\\myenv\\Lib\\site-packages\\pluggy\\_result.py\", line 103, in get_result\n    raise exc.with_traceback(tb)\n  File \"D:\\my_venv\\myenv\\Lib\\site-packages\\pluggy\\_callers.py\", line 38, in run_old_style_hookwrapper\n    res = yield\n          ^^^^^\n  File \"D:\\my_venv\\myenv\\Lib\\site-packages\\pluggy\\_callers.py\", line 139, in _multicall\n    teardown.throw(exception)\n  File \"D:\\my_venv\\myenv\\Lib\\site-packages\\_pytest\\setuponly.py\", line 36, in pytest_fixture_setup\n    return (yield)\n            ^^^^^\n  File \"D:\\my_venv\\myenv\\Lib\\site-packages\\pluggy\\_callers.py\", line 121, in _multicall\n    res = hook_impl.function(*args)\n          ^^^^^^^^^^^^^^^^^^^^^^^^^\n  File \"D:\\my_venv\\myenv\\Lib\\site-packages\\_pytest\\fixtures.py\", line 1195, in pytest_fixture_setup\n    result = call_fixture_func(fixturefunc, request, kwargs)\n             ^^^^^^^^^^^^^^^^^^^^^^^^^^^^^^^^^^^^^^^^^^^^^^^\n  File \"D:\\my_venv\\myenv\\Lib\\site-packages\\_pytest\\fixtures.py\", line 922, in call_fixture_func\n    fixture_result = next(generator)\n                     ^^^^^^^^^^^^^^^\n  File \"D:\\my_venv\\myenv\\Lib\\site-packages\\_pytest\\python.py\", line 792, in xunit_setup_class_fixture\n    _call_with_optional_argument(func, cls)\n  File \"D:\\my_venv\\myenv\\Lib\\site-packages\\_pytest\\python.py\", line 720, in _call_with_optional_argument\n    func(arg)\n  File \"D:\\pythonProject3\\autotest_api\\test_case\\test_pending_risk_event\\test_risk_mid.py\", line 28, in setup_class\n    pytest.fail(\"setup_class: 未获取到 token\")\n  File \"D:\\my_venv\\myenv\\Lib\\site-packages\\_pytest\\outcomes.py\", line 177, in fail\n    raise Failed(msg=reason, pytrace=pytrace)\n"}, "steps": [{"name": "【风险】-【风险事件列表】接口", "status": "failed", "statusDetails": {"message": "Failed: setup_class: 未获取到 token\n", "trace": "  File \"D:\\pythonProject3\\autotest_api\\test_case\\test_pending_risk_event\\test_risk_mid.py\", line 28, in setup_class\n    pytest.fail(\"setup_class: 未获取到 token\")\n  File \"D:\\my_venv\\myenv\\Lib\\site-packages\\_pytest\\outcomes.py\", line 177, in fail\n    raise Failed(msg=reason, pytrace=pytrace)\n"}, "start": 1754031301034, "stop": 1754031301034}], "start": 1754031301034, "stop": 1754031301035}], "start": 1754031301034, "stop": 1754031301048}