{"uuid": "3e263e60-a3c4-4bb3-8587-821596c2edb9", "children": ["8e8bb0f0-c2d8-46bd-8188-18f4acf75162", "599647f1-948d-4b62-932d-05818b021d5b", "60770e99-6190-4348-b5ac-2f9c995549aa", "344c0bb4-3cf4-4a95-80b4-e6d98efe189d"], "befores": [{"name": "_xunit_setup_class_fixture_TestCase", "status": "failed", "statusDetails": {"message": "Failed: setup_class: 未获取到 token\n", "trace": "  File \"D:\\my_venv\\myenv\\Lib\\site-packages\\pluggy\\_callers.py\", line 38, in run_old_style_hookwrapper\n    res = yield\n          ^^^^^\n  File \"D:\\my_venv\\myenv\\Lib\\site-packages\\pluggy\\_callers.py\", line 139, in _multicall\n    teardown.throw(exception)\n  File \"D:\\my_venv\\myenv\\Lib\\site-packages\\pluggy\\_callers.py\", line 53, in run_old_style_hookwrapper\n    return result.get_result()\n           ^^^^^^^^^^^^^^^^^^^\n  File \"D:\\my_venv\\myenv\\Lib\\site-packages\\pluggy\\_result.py\", line 103, in get_result\n    raise exc.with_traceback(tb)\n  File \"D:\\my_venv\\myenv\\Lib\\site-packages\\pluggy\\_callers.py\", line 38, in run_old_style_hookwrapper\n    res = yield\n          ^^^^^\n  File \"D:\\my_venv\\myenv\\Lib\\site-packages\\pluggy\\_callers.py\", line 139, in _multicall\n    teardown.throw(exception)\n  File \"D:\\my_venv\\myenv\\Lib\\site-packages\\_pytest\\setuponly.py\", line 36, in pytest_fixture_setup\n    return (yield)\n            ^^^^^\n  File \"D:\\my_venv\\myenv\\Lib\\site-packages\\pluggy\\_callers.py\", line 121, in _multicall\n    res = hook_impl.function(*args)\n          ^^^^^^^^^^^^^^^^^^^^^^^^^\n  File \"D:\\my_venv\\myenv\\Lib\\site-packages\\_pytest\\fixtures.py\", line 1195, in pytest_fixture_setup\n    result = call_fixture_func(fixturefunc, request, kwargs)\n             ^^^^^^^^^^^^^^^^^^^^^^^^^^^^^^^^^^^^^^^^^^^^^^^\n  File \"D:\\my_venv\\myenv\\Lib\\site-packages\\_pytest\\fixtures.py\", line 922, in call_fixture_func\n    fixture_result = next(generator)\n                     ^^^^^^^^^^^^^^^\n  File \"D:\\my_venv\\myenv\\Lib\\site-packages\\_pytest\\python.py\", line 792, in xunit_setup_class_fixture\n    _call_with_optional_argument(func, cls)\n  File \"D:\\my_venv\\myenv\\Lib\\site-packages\\_pytest\\python.py\", line 720, in _call_with_optional_argument\n    func(arg)\n  File \"D:\\pythonProject3\\autotest_api\\test_case\\test_pending_vul_event\\test_vul_mid.py\", line 28, in setup_class\n    pytest.fail(\"setup_class: 未获取到 token\")\n  File \"D:\\my_venv\\myenv\\Lib\\site-packages\\_pytest\\outcomes.py\", line 177, in fail\n    raise Failed(msg=reason, pytrace=pytrace)\n"}, "steps": [{"name": "【弱点】-【弱点事件列表】接口", "status": "failed", "statusDetails": {"message": "Failed: setup_class: 未获取到 token\n", "trace": "  File \"D:\\pythonProject3\\autotest_api\\test_case\\test_pending_vul_event\\test_vul_mid.py\", line 28, in setup_class\n    pytest.fail(\"setup_class: 未获取到 token\")\n  File \"D:\\my_venv\\myenv\\Lib\\site-packages\\_pytest\\outcomes.py\", line 177, in fail\n    raise Failed(msg=reason, pytrace=pytrace)\n"}, "start": 1754031294582, "stop": 1754031294582}], "start": 1754031294582, "stop": 1754031294600}, {"name": "_xunit_setup_class_fixture_TestCase", "status": "failed", "statusDetails": {"message": "Failed: setup_class: 未获取到 token\n", "trace": "  File \"D:\\my_venv\\myenv\\Lib\\site-packages\\pluggy\\_callers.py\", line 38, in run_old_style_hookwrapper\n    res = yield\n          ^^^^^\n  File \"D:\\my_venv\\myenv\\Lib\\site-packages\\pluggy\\_callers.py\", line 139, in _multicall\n    teardown.throw(exception)\n  File \"D:\\my_venv\\myenv\\Lib\\site-packages\\pluggy\\_callers.py\", line 53, in run_old_style_hookwrapper\n    return result.get_result()\n           ^^^^^^^^^^^^^^^^^^^\n  File \"D:\\my_venv\\myenv\\Lib\\site-packages\\pluggy\\_result.py\", line 103, in get_result\n    raise exc.with_traceback(tb)\n  File \"D:\\my_venv\\myenv\\Lib\\site-packages\\pluggy\\_callers.py\", line 38, in run_old_style_hookwrapper\n    res = yield\n          ^^^^^\n  File \"D:\\my_venv\\myenv\\Lib\\site-packages\\pluggy\\_callers.py\", line 139, in _multicall\n    teardown.throw(exception)\n  File \"D:\\my_venv\\myenv\\Lib\\site-packages\\_pytest\\setuponly.py\", line 36, in pytest_fixture_setup\n    return (yield)\n            ^^^^^\n  File \"D:\\my_venv\\myenv\\Lib\\site-packages\\pluggy\\_callers.py\", line 121, in _multicall\n    res = hook_impl.function(*args)\n          ^^^^^^^^^^^^^^^^^^^^^^^^^\n  File \"D:\\my_venv\\myenv\\Lib\\site-packages\\_pytest\\fixtures.py\", line 1195, in pytest_fixture_setup\n    result = call_fixture_func(fixturefunc, request, kwargs)\n             ^^^^^^^^^^^^^^^^^^^^^^^^^^^^^^^^^^^^^^^^^^^^^^^\n  File \"D:\\my_venv\\myenv\\Lib\\site-packages\\_pytest\\fixtures.py\", line 922, in call_fixture_func\n    fixture_result = next(generator)\n                     ^^^^^^^^^^^^^^^\n  File \"D:\\my_venv\\myenv\\Lib\\site-packages\\_pytest\\python.py\", line 792, in xunit_setup_class_fixture\n    _call_with_optional_argument(func, cls)\n  File \"D:\\my_venv\\myenv\\Lib\\site-packages\\_pytest\\python.py\", line 720, in _call_with_optional_argument\n    func(arg)\n  File \"D:\\pythonProject3\\autotest_api\\test_case\\test_pending_vul_event\\test_vul_mid.py\", line 28, in setup_class\n    pytest.fail(\"setup_class: 未获取到 token\")\n  File \"D:\\my_venv\\myenv\\Lib\\site-packages\\_pytest\\outcomes.py\", line 177, in fail\n    raise Failed(msg=reason, pytrace=pytrace)\n"}, "steps": [{"name": "【弱点】-【弱点事件列表】接口", "status": "failed", "statusDetails": {"message": "Failed: setup_class: 未获取到 token\n", "trace": "  File \"D:\\pythonProject3\\autotest_api\\test_case\\test_pending_vul_event\\test_vul_mid.py\", line 28, in setup_class\n    pytest.fail(\"setup_class: 未获取到 token\")\n  File \"D:\\my_venv\\myenv\\Lib\\site-packages\\_pytest\\outcomes.py\", line 177, in fail\n    raise Failed(msg=reason, pytrace=pytrace)\n"}, "start": 1754031295894, "stop": 1754031295894}], "start": 1754031295893, "stop": 1754031295894}, {"name": "_xunit_setup_class_fixture_TestCase", "status": "failed", "statusDetails": {"message": "Failed: setup_class: 未获取到 token\n", "trace": "  File \"D:\\my_venv\\myenv\\Lib\\site-packages\\pluggy\\_callers.py\", line 38, in run_old_style_hookwrapper\n    res = yield\n          ^^^^^\n  File \"D:\\my_venv\\myenv\\Lib\\site-packages\\pluggy\\_callers.py\", line 139, in _multicall\n    teardown.throw(exception)\n  File \"D:\\my_venv\\myenv\\Lib\\site-packages\\pluggy\\_callers.py\", line 53, in run_old_style_hookwrapper\n    return result.get_result()\n           ^^^^^^^^^^^^^^^^^^^\n  File \"D:\\my_venv\\myenv\\Lib\\site-packages\\pluggy\\_result.py\", line 103, in get_result\n    raise exc.with_traceback(tb)\n  File \"D:\\my_venv\\myenv\\Lib\\site-packages\\pluggy\\_callers.py\", line 38, in run_old_style_hookwrapper\n    res = yield\n          ^^^^^\n  File \"D:\\my_venv\\myenv\\Lib\\site-packages\\pluggy\\_callers.py\", line 139, in _multicall\n    teardown.throw(exception)\n  File \"D:\\my_venv\\myenv\\Lib\\site-packages\\_pytest\\setuponly.py\", line 36, in pytest_fixture_setup\n    return (yield)\n            ^^^^^\n  File \"D:\\my_venv\\myenv\\Lib\\site-packages\\pluggy\\_callers.py\", line 121, in _multicall\n    res = hook_impl.function(*args)\n          ^^^^^^^^^^^^^^^^^^^^^^^^^\n  File \"D:\\my_venv\\myenv\\Lib\\site-packages\\_pytest\\fixtures.py\", line 1195, in pytest_fixture_setup\n    result = call_fixture_func(fixturefunc, request, kwargs)\n             ^^^^^^^^^^^^^^^^^^^^^^^^^^^^^^^^^^^^^^^^^^^^^^^\n  File \"D:\\my_venv\\myenv\\Lib\\site-packages\\_pytest\\fixtures.py\", line 922, in call_fixture_func\n    fixture_result = next(generator)\n                     ^^^^^^^^^^^^^^^\n  File \"D:\\my_venv\\myenv\\Lib\\site-packages\\_pytest\\python.py\", line 792, in xunit_setup_class_fixture\n    _call_with_optional_argument(func, cls)\n  File \"D:\\my_venv\\myenv\\Lib\\site-packages\\_pytest\\python.py\", line 720, in _call_with_optional_argument\n    func(arg)\n  File \"D:\\pythonProject3\\autotest_api\\test_case\\test_pending_vul_event\\test_vul_mid.py\", line 28, in setup_class\n    pytest.fail(\"setup_class: 未获取到 token\")\n  File \"D:\\my_venv\\myenv\\Lib\\site-packages\\_pytest\\outcomes.py\", line 177, in fail\n    raise Failed(msg=reason, pytrace=pytrace)\n"}, "steps": [{"name": "【弱点】-【弱点事件列表】接口", "status": "failed", "statusDetails": {"message": "Failed: setup_class: 未获取到 token\n", "trace": "  File \"D:\\pythonProject3\\autotest_api\\test_case\\test_pending_vul_event\\test_vul_mid.py\", line 28, in setup_class\n    pytest.fail(\"setup_class: 未获取到 token\")\n  File \"D:\\my_venv\\myenv\\Lib\\site-packages\\_pytest\\outcomes.py\", line 177, in fail\n    raise Failed(msg=reason, pytrace=pytrace)\n"}, "start": 1754031296907, "stop": 1754031296907}], "start": 1754031296907, "stop": 1754031296909}, {"name": "_xunit_setup_class_fixture_TestCase", "status": "failed", "statusDetails": {"message": "Failed: setup_class: 未获取到 token\n", "trace": "  File \"D:\\my_venv\\myenv\\Lib\\site-packages\\pluggy\\_callers.py\", line 38, in run_old_style_hookwrapper\n    res = yield\n          ^^^^^\n  File \"D:\\my_venv\\myenv\\Lib\\site-packages\\pluggy\\_callers.py\", line 139, in _multicall\n    teardown.throw(exception)\n  File \"D:\\my_venv\\myenv\\Lib\\site-packages\\pluggy\\_callers.py\", line 53, in run_old_style_hookwrapper\n    return result.get_result()\n           ^^^^^^^^^^^^^^^^^^^\n  File \"D:\\my_venv\\myenv\\Lib\\site-packages\\pluggy\\_result.py\", line 103, in get_result\n    raise exc.with_traceback(tb)\n  File \"D:\\my_venv\\myenv\\Lib\\site-packages\\pluggy\\_callers.py\", line 38, in run_old_style_hookwrapper\n    res = yield\n          ^^^^^\n  File \"D:\\my_venv\\myenv\\Lib\\site-packages\\pluggy\\_callers.py\", line 139, in _multicall\n    teardown.throw(exception)\n  File \"D:\\my_venv\\myenv\\Lib\\site-packages\\_pytest\\setuponly.py\", line 36, in pytest_fixture_setup\n    return (yield)\n            ^^^^^\n  File \"D:\\my_venv\\myenv\\Lib\\site-packages\\pluggy\\_callers.py\", line 121, in _multicall\n    res = hook_impl.function(*args)\n          ^^^^^^^^^^^^^^^^^^^^^^^^^\n  File \"D:\\my_venv\\myenv\\Lib\\site-packages\\_pytest\\fixtures.py\", line 1195, in pytest_fixture_setup\n    result = call_fixture_func(fixturefunc, request, kwargs)\n             ^^^^^^^^^^^^^^^^^^^^^^^^^^^^^^^^^^^^^^^^^^^^^^^\n  File \"D:\\my_venv\\myenv\\Lib\\site-packages\\_pytest\\fixtures.py\", line 922, in call_fixture_func\n    fixture_result = next(generator)\n                     ^^^^^^^^^^^^^^^\n  File \"D:\\my_venv\\myenv\\Lib\\site-packages\\_pytest\\python.py\", line 792, in xunit_setup_class_fixture\n    _call_with_optional_argument(func, cls)\n  File \"D:\\my_venv\\myenv\\Lib\\site-packages\\_pytest\\python.py\", line 720, in _call_with_optional_argument\n    func(arg)\n  File \"D:\\pythonProject3\\autotest_api\\test_case\\test_pending_vul_event\\test_vul_mid.py\", line 28, in setup_class\n    pytest.fail(\"setup_class: 未获取到 token\")\n  File \"D:\\my_venv\\myenv\\Lib\\site-packages\\_pytest\\outcomes.py\", line 177, in fail\n    raise Failed(msg=reason, pytrace=pytrace)\n"}, "steps": [{"name": "【弱点】-【弱点事件列表】接口", "status": "failed", "statusDetails": {"message": "Failed: setup_class: 未获取到 token\n", "trace": "  File \"D:\\pythonProject3\\autotest_api\\test_case\\test_pending_vul_event\\test_vul_mid.py\", line 28, in setup_class\n    pytest.fail(\"setup_class: 未获取到 token\")\n  File \"D:\\my_venv\\myenv\\Lib\\site-packages\\_pytest\\outcomes.py\", line 177, in fail\n    raise Failed(msg=reason, pytrace=pytrace)\n"}, "start": 1754031297919, "stop": 1754031297919}], "start": 1754031297919, "stop": 1754031297920}], "start": 1754031297919, "stop": 1754031297928}